[2025-06-12T08:07:08.455+0000] {taskinstance.py:1103} INFO - Dependencies all met for dep_context=non-requeueable deps ti=<TaskInstance: yfinance_pipeline.load_yfinance scheduled__2025-06-11T00:00:00+00:00 [queued]>
[2025-06-12T08:07:08.471+0000] {taskinstance.py:1103} INFO - Dependencies all met for dep_context=requeueable deps ti=<TaskInstance: yfinance_pipeline.load_yfinance scheduled__2025-06-11T00:00:00+00:00 [queued]>
[2025-06-12T08:07:08.472+0000] {taskinstance.py:1308} INFO - Starting attempt 2 of 2
[2025-06-12T08:07:08.508+0000] {taskinstance.py:1327} INFO - Executing <Task(DockerOperator): load_yfinance> on 2025-06-11 00:00:00+00:00
[2025-06-12T08:07:08.519+0000] {standard_task_runner.py:57} INFO - Started process 548 to run task
[2025-06-12T08:07:08.525+0000] {standard_task_runner.py:84} INFO - Running: ['***', 'tasks', 'run', 'yfinance_pipeline', 'load_yfinance', 'scheduled__2025-06-11T00:00:00+00:00', '--job-id', '17', '--raw', '--subdir', 'DAGS_FOLDER/yfinance_pipeline_dag.py', '--cfg-path', '/tmp/tmpp2qka4x2']
[2025-06-12T08:07:08.527+0000] {standard_task_runner.py:85} INFO - Job 17: Subtask load_yfinance
[2025-06-12T08:07:08.623+0000] {task_command.py:410} INFO - Running <TaskInstance: yfinance_pipeline.load_yfinance scheduled__2025-06-11T00:00:00+00:00 [running]> on host 88a1aa7b4be9
[2025-06-12T08:07:08.913+0000] {taskinstance.py:1547} INFO - Exporting env vars: AIRFLOW_CTX_DAG_OWNER='***' AIRFLOW_CTX_DAG_ID='yfinance_pipeline' AIRFLOW_CTX_TASK_ID='load_yfinance' AIRFLOW_CTX_EXECUTION_DATE='2025-06-11T00:00:00+00:00' AIRFLOW_CTX_TRY_NUMBER='2' AIRFLOW_CTX_DAG_RUN_ID='scheduled__2025-06-11T00:00:00+00:00'
[2025-06-12T08:07:09.021+0000] {docker.py:334} INFO - Starting docker container from image yfinance-load:latest
[2025-06-12T08:07:11.524+0000] {docker.py:403} INFO - 2025-06-12 08:07:11,521 - __main__ - INFO - ======================================================================
2025-06-12 08:07:11,521 - __main__ - INFO - ðŸš€ YFINANCE AUTO-LOAD TO 7 COLLECTIONS WITH DIFFERENT PERIODS
2025-06-12 08:07:11,521 - __main__ - INFO - ======================================================================
2025-06-12 08:07:11,521 - __main__ - INFO - Start time: 2025-06-12 08:07:11
2025-06-12 08:07:11,521 - __main__ - INFO - Loading from: /app/output/tickers_data.json
[2025-06-12T08:07:11.526+0000] {docker.py:403} INFO - 2025-06-12 08:07:11,521 - __main__ - INFO - Target database: bigdata_saham
[2025-06-12T08:07:11.527+0000] {docker.py:403} INFO - 2025-06-12 08:07:11,521 - __main__ - INFO - Target collections: ['data_harian', 'data_mingguan', 'data_bulanan', 'data_tahunan', 'data_lima_tahun', 'data_satu_tahun', 'data_tiga_tahun']
[2025-06-12T08:08:01.120+0000] {job.py:213} ERROR - Job heartbeat got an exception
Traceback (most recent call last):
  File "/home/airflow/.local/lib/python3.7/site-packages/sqlalchemy/engine/base.py", line 3371, in _wrap_pool_connect
    return fn()
  File "/home/airflow/.local/lib/python3.7/site-packages/sqlalchemy/pool/base.py", line 327, in connect
    return _ConnectionFairy._checkout(self)
  File "/home/airflow/.local/lib/python3.7/site-packages/sqlalchemy/pool/base.py", line 894, in _checkout
    fairy = _ConnectionRecord.checkout(pool)
  File "/home/airflow/.local/lib/python3.7/site-packages/sqlalchemy/pool/base.py", line 493, in checkout
    rec = pool._do_get()
  File "/home/airflow/.local/lib/python3.7/site-packages/sqlalchemy/pool/impl.py", line 256, in _do_get
    return self._create_connection()
  File "/home/airflow/.local/lib/python3.7/site-packages/sqlalchemy/pool/base.py", line 273, in _create_connection
    return _ConnectionRecord(self)
  File "/home/airflow/.local/lib/python3.7/site-packages/sqlalchemy/pool/base.py", line 388, in __init__
    self.__connect()
  File "/home/airflow/.local/lib/python3.7/site-packages/sqlalchemy/pool/base.py", line 691, in __connect
    pool.logger.debug("Error on connect(): %s", e)
  File "/home/airflow/.local/lib/python3.7/site-packages/sqlalchemy/util/langhelpers.py", line 72, in __exit__
    with_traceback=exc_tb,
  File "/home/airflow/.local/lib/python3.7/site-packages/sqlalchemy/util/compat.py", line 211, in raise_
    raise exception
  File "/home/airflow/.local/lib/python3.7/site-packages/sqlalchemy/pool/base.py", line 686, in __connect
    self.dbapi_connection = connection = pool._invoke_creator(self)
  File "/home/airflow/.local/lib/python3.7/site-packages/sqlalchemy/engine/create.py", line 574, in connect
    return dialect.connect(*cargs, **cparams)
  File "/home/airflow/.local/lib/python3.7/site-packages/sqlalchemy/engine/default.py", line 598, in connect
    return self.dbapi.connect(*cargs, **cparams)
  File "/home/airflow/.local/lib/python3.7/site-packages/psycopg2/__init__.py", line 122, in connect
    conn = _connect(dsn, connection_factory=connection_factory, **kwasync)
psycopg2.OperationalError: could not translate host name "postgres" to address: Temporary failure in name resolution


The above exception was the direct cause of the following exception:

Traceback (most recent call last):
  File "/home/airflow/.local/lib/python3.7/site-packages/airflow/jobs/job.py", line 184, in heartbeat
    session.merge(self)
  File "/home/airflow/.local/lib/python3.7/site-packages/sqlalchemy/orm/session.py", line 3062, in merge
    _resolve_conflict_map=_resolve_conflict_map,
  File "/home/airflow/.local/lib/python3.7/site-packages/sqlalchemy/orm/session.py", line 3140, in _merge
    options=options,
  File "/home/airflow/.local/lib/python3.7/site-packages/sqlalchemy/orm/session.py", line 2861, in get
    execution_options=execution_options,
  File "/home/airflow/.local/lib/python3.7/site-packages/sqlalchemy/orm/session.py", line 2979, in _get_impl
    load_options=load_options,
  File "/home/airflow/.local/lib/python3.7/site-packages/sqlalchemy/orm/loading.py", line 534, in load_on_pk_identity
    bind_arguments=bind_arguments,
  File "/home/airflow/.local/lib/python3.7/site-packages/sqlalchemy/orm/session.py", line 1716, in execute
    conn = self._connection_for_bind(bind)
  File "/home/airflow/.local/lib/python3.7/site-packages/sqlalchemy/orm/session.py", line 1556, in _connection_for_bind
    engine, execution_options
  File "/home/airflow/.local/lib/python3.7/site-packages/sqlalchemy/orm/session.py", line 750, in _connection_for_bind
    conn = bind.connect()
  File "/home/airflow/.local/lib/python3.7/site-packages/sqlalchemy/engine/base.py", line 3325, in connect
    return self._connection_cls(self, close_with_result=close_with_result)
  File "/home/airflow/.local/lib/python3.7/site-packages/sqlalchemy/engine/base.py", line 96, in __init__
    else engine.raw_connection()
  File "/home/airflow/.local/lib/python3.7/site-packages/sqlalchemy/engine/base.py", line 3404, in raw_connection
    return self._wrap_pool_connect(self.pool.connect, _connection)
  File "/home/airflow/.local/lib/python3.7/site-packages/sqlalchemy/engine/base.py", line 3375, in _wrap_pool_connect
    e, dialect, self
  File "/home/airflow/.local/lib/python3.7/site-packages/sqlalchemy/engine/base.py", line 2209, in _handle_dbapi_exception_noconnection
    sqlalchemy_exception, with_traceback=exc_info[2], from_=e
  File "/home/airflow/.local/lib/python3.7/site-packages/sqlalchemy/util/compat.py", line 211, in raise_
    raise exception
  File "/home/airflow/.local/lib/python3.7/site-packages/sqlalchemy/engine/base.py", line 3371, in _wrap_pool_connect
    return fn()
  File "/home/airflow/.local/lib/python3.7/site-packages/sqlalchemy/pool/base.py", line 327, in connect
    return _ConnectionFairy._checkout(self)
  File "/home/airflow/.local/lib/python3.7/site-packages/sqlalchemy/pool/base.py", line 894, in _checkout
    fairy = _ConnectionRecord.checkout(pool)
  File "/home/airflow/.local/lib/python3.7/site-packages/sqlalchemy/pool/base.py", line 493, in checkout
    rec = pool._do_get()
  File "/home/airflow/.local/lib/python3.7/site-packages/sqlalchemy/pool/impl.py", line 256, in _do_get
    return self._create_connection()
  File "/home/airflow/.local/lib/python3.7/site-packages/sqlalchemy/pool/base.py", line 273, in _create_connection
    return _ConnectionRecord(self)
  File "/home/airflow/.local/lib/python3.7/site-packages/sqlalchemy/pool/base.py", line 388, in __init__
    self.__connect()
  File "/home/airflow/.local/lib/python3.7/site-packages/sqlalchemy/pool/base.py", line 691, in __connect
    pool.logger.debug("Error on connect(): %s", e)
  File "/home/airflow/.local/lib/python3.7/site-packages/sqlalchemy/util/langhelpers.py", line 72, in __exit__
    with_traceback=exc_tb,
  File "/home/airflow/.local/lib/python3.7/site-packages/sqlalchemy/util/compat.py", line 211, in raise_
    raise exception
  File "/home/airflow/.local/lib/python3.7/site-packages/sqlalchemy/pool/base.py", line 686, in __connect
    self.dbapi_connection = connection = pool._invoke_creator(self)
  File "/home/airflow/.local/lib/python3.7/site-packages/sqlalchemy/engine/create.py", line 574, in connect
    return dialect.connect(*cargs, **cparams)
  File "/home/airflow/.local/lib/python3.7/site-packages/sqlalchemy/engine/default.py", line 598, in connect
    return self.dbapi.connect(*cargs, **cparams)
  File "/home/airflow/.local/lib/python3.7/site-packages/psycopg2/__init__.py", line 122, in connect
    conn = _connect(dsn, connection_factory=connection_factory, **kwasync)
sqlalchemy.exc.OperationalError: (psycopg2.OperationalError) could not translate host name "postgres" to address: Temporary failure in name resolution

(Background on this error at: https://sqlalche.me/e/14/e3q8)
[2025-06-12T08:08:45.007+0000] {job.py:213} ERROR - Job heartbeat got an exception
Traceback (most recent call last):
  File "/home/airflow/.local/lib/python3.7/site-packages/sqlalchemy/engine/base.py", line 3371, in _wrap_pool_connect
    return fn()
  File "/home/airflow/.local/lib/python3.7/site-packages/sqlalchemy/pool/base.py", line 327, in connect
    return _ConnectionFairy._checkout(self)
  File "/home/airflow/.local/lib/python3.7/site-packages/sqlalchemy/pool/base.py", line 894, in _checkout
    fairy = _ConnectionRecord.checkout(pool)
  File "/home/airflow/.local/lib/python3.7/site-packages/sqlalchemy/pool/base.py", line 493, in checkout
    rec = pool._do_get()
  File "/home/airflow/.local/lib/python3.7/site-packages/sqlalchemy/pool/impl.py", line 256, in _do_get
    return self._create_connection()
  File "/home/airflow/.local/lib/python3.7/site-packages/sqlalchemy/pool/base.py", line 273, in _create_connection
    return _ConnectionRecord(self)
  File "/home/airflow/.local/lib/python3.7/site-packages/sqlalchemy/pool/base.py", line 388, in __init__
    self.__connect()
  File "/home/airflow/.local/lib/python3.7/site-packages/sqlalchemy/pool/base.py", line 691, in __connect
    pool.logger.debug("Error on connect(): %s", e)
  File "/home/airflow/.local/lib/python3.7/site-packages/sqlalchemy/util/langhelpers.py", line 72, in __exit__
    with_traceback=exc_tb,
  File "/home/airflow/.local/lib/python3.7/site-packages/sqlalchemy/util/compat.py", line 211, in raise_
    raise exception
  File "/home/airflow/.local/lib/python3.7/site-packages/sqlalchemy/pool/base.py", line 686, in __connect
    self.dbapi_connection = connection = pool._invoke_creator(self)
  File "/home/airflow/.local/lib/python3.7/site-packages/sqlalchemy/engine/create.py", line 574, in connect
    return dialect.connect(*cargs, **cparams)
  File "/home/airflow/.local/lib/python3.7/site-packages/sqlalchemy/engine/default.py", line 598, in connect
    return self.dbapi.connect(*cargs, **cparams)
  File "/home/airflow/.local/lib/python3.7/site-packages/psycopg2/__init__.py", line 122, in connect
    conn = _connect(dsn, connection_factory=connection_factory, **kwasync)
psycopg2.OperationalError: could not translate host name "postgres" to address: Temporary failure in name resolution


The above exception was the direct cause of the following exception:

Traceback (most recent call last):
  File "/home/airflow/.local/lib/python3.7/site-packages/airflow/jobs/job.py", line 184, in heartbeat
    session.merge(self)
  File "/home/airflow/.local/lib/python3.7/site-packages/sqlalchemy/orm/session.py", line 3062, in merge
    _resolve_conflict_map=_resolve_conflict_map,
  File "/home/airflow/.local/lib/python3.7/site-packages/sqlalchemy/orm/session.py", line 3140, in _merge
    options=options,
  File "/home/airflow/.local/lib/python3.7/site-packages/sqlalchemy/orm/session.py", line 2861, in get
    execution_options=execution_options,
  File "/home/airflow/.local/lib/python3.7/site-packages/sqlalchemy/orm/session.py", line 2979, in _get_impl
    load_options=load_options,
  File "/home/airflow/.local/lib/python3.7/site-packages/sqlalchemy/orm/loading.py", line 534, in load_on_pk_identity
    bind_arguments=bind_arguments,
  File "/home/airflow/.local/lib/python3.7/site-packages/sqlalchemy/orm/session.py", line 1716, in execute
    conn = self._connection_for_bind(bind)
  File "/home/airflow/.local/lib/python3.7/site-packages/sqlalchemy/orm/session.py", line 1556, in _connection_for_bind
    engine, execution_options
  File "/home/airflow/.local/lib/python3.7/site-packages/sqlalchemy/orm/session.py", line 750, in _connection_for_bind
    conn = bind.connect()
  File "/home/airflow/.local/lib/python3.7/site-packages/sqlalchemy/engine/base.py", line 3325, in connect
    return self._connection_cls(self, close_with_result=close_with_result)
  File "/home/airflow/.local/lib/python3.7/site-packages/sqlalchemy/engine/base.py", line 96, in __init__
    else engine.raw_connection()
  File "/home/airflow/.local/lib/python3.7/site-packages/sqlalchemy/engine/base.py", line 3404, in raw_connection
    return self._wrap_pool_connect(self.pool.connect, _connection)
  File "/home/airflow/.local/lib/python3.7/site-packages/sqlalchemy/engine/base.py", line 3375, in _wrap_pool_connect
    e, dialect, self
  File "/home/airflow/.local/lib/python3.7/site-packages/sqlalchemy/engine/base.py", line 2209, in _handle_dbapi_exception_noconnection
    sqlalchemy_exception, with_traceback=exc_info[2], from_=e
  File "/home/airflow/.local/lib/python3.7/site-packages/sqlalchemy/util/compat.py", line 211, in raise_
    raise exception
  File "/home/airflow/.local/lib/python3.7/site-packages/sqlalchemy/engine/base.py", line 3371, in _wrap_pool_connect
    return fn()
  File "/home/airflow/.local/lib/python3.7/site-packages/sqlalchemy/pool/base.py", line 327, in connect
    return _ConnectionFairy._checkout(self)
  File "/home/airflow/.local/lib/python3.7/site-packages/sqlalchemy/pool/base.py", line 894, in _checkout
    fairy = _ConnectionRecord.checkout(pool)
  File "/home/airflow/.local/lib/python3.7/site-packages/sqlalchemy/pool/base.py", line 493, in checkout
    rec = pool._do_get()
  File "/home/airflow/.local/lib/python3.7/site-packages/sqlalchemy/pool/impl.py", line 256, in _do_get
    return self._create_connection()
  File "/home/airflow/.local/lib/python3.7/site-packages/sqlalchemy/pool/base.py", line 273, in _create_connection
    return _ConnectionRecord(self)
  File "/home/airflow/.local/lib/python3.7/site-packages/sqlalchemy/pool/base.py", line 388, in __init__
    self.__connect()
  File "/home/airflow/.local/lib/python3.7/site-packages/sqlalchemy/pool/base.py", line 691, in __connect
    pool.logger.debug("Error on connect(): %s", e)
  File "/home/airflow/.local/lib/python3.7/site-packages/sqlalchemy/util/langhelpers.py", line 72, in __exit__
    with_traceback=exc_tb,
  File "/home/airflow/.local/lib/python3.7/site-packages/sqlalchemy/util/compat.py", line 211, in raise_
    raise exception
  File "/home/airflow/.local/lib/python3.7/site-packages/sqlalchemy/pool/base.py", line 686, in __connect
    self.dbapi_connection = connection = pool._invoke_creator(self)
  File "/home/airflow/.local/lib/python3.7/site-packages/sqlalchemy/engine/create.py", line 574, in connect
    return dialect.connect(*cargs, **cparams)
  File "/home/airflow/.local/lib/python3.7/site-packages/sqlalchemy/engine/default.py", line 598, in connect
    return self.dbapi.connect(*cargs, **cparams)
  File "/home/airflow/.local/lib/python3.7/site-packages/psycopg2/__init__.py", line 122, in connect
    conn = _connect(dsn, connection_factory=connection_factory, **kwasync)
sqlalchemy.exc.OperationalError: (psycopg2.OperationalError) could not translate host name "postgres" to address: Temporary failure in name resolution

(Background on this error at: https://sqlalche.me/e/14/e3q8)
[2025-06-12T08:09:44.263+0000] {taskinstance.py:1824} ERROR - Task failed with exception
Traceback (most recent call last):
  File "/home/airflow/.local/lib/python3.7/site-packages/airflow/providers/docker/operators/docker.py", line 478, in execute
    return self._run_image()
  File "/home/airflow/.local/lib/python3.7/site-packages/airflow/providers/docker/operators/docker.py", line 351, in _run_image
    return self._run_image_with_mounts(self.mounts, add_tmp_variable=False)
  File "/home/airflow/.local/lib/python3.7/site-packages/airflow/providers/docker/operators/docker.py", line 412, in _run_image_with_mounts
    raise AirflowException(f"Docker container failed: {repr(result)} lines {joined_log_lines}")
airflow.exceptions.AirflowException: Docker container failed: {'StatusCode': 137} lines 2025-06-12 08:07:11,521 - __main__ - INFO - ======================================================================
2025-06-12 08:07:11,521 - __main__ - INFO - ðŸš€ YFINANCE AUTO-LOAD TO 7 COLLECTIONS WITH DIFFERENT PERIODS
2025-06-12 08:07:11,521 - __main__ - INFO - ======================================================================
2025-06-12 08:07:11,521 - __main__ - INFO - Start time: 2025-06-12 08:07:11
2025-06-12 08:07:11,521 - __main__ - INFO - Loading from: /app/output/tickers_data.json
2025-06-12 08:07:11,521 - __main__ - INFO - Target database: bigdata_saham
2025-06-12 08:07:11,521 - __main__ - INFO - Target collections: ['data_harian', 'data_mingguan', 'data_bulanan', 'data_tahunan', 'data_lima_tahun', 'data_satu_tahun', 'data_tiga_tahun']
[2025-06-12T08:09:44.325+0000] {taskinstance.py:1350} INFO - Marking task as FAILED. dag_id=yfinance_pipeline, task_id=load_yfinance, execution_date=20250611T000000, start_date=20250612T080708, end_date=20250612T080944
[2025-06-12T08:09:44.456+0000] {standard_task_runner.py:109} ERROR - Failed to execute job 17 for task load_yfinance (Docker container failed: {'StatusCode': 137} lines 2025-06-12 08:07:11,521 - __main__ - INFO - ======================================================================
2025-06-12 08:07:11,521 - __main__ - INFO - ðŸš€ YFINANCE AUTO-LOAD TO 7 COLLECTIONS WITH DIFFERENT PERIODS
2025-06-12 08:07:11,521 - __main__ - INFO - ======================================================================
2025-06-12 08:07:11,521 - __main__ - INFO - Start time: 2025-06-12 08:07:11
2025-06-12 08:07:11,521 - __main__ - INFO - Loading from: /app/output/tickers_data.json
2025-06-12 08:07:11,521 - __main__ - INFO - Target database: bigdata_saham
2025-06-12 08:07:11,521 - __main__ - INFO - Target collections: ['data_harian', 'data_mingguan', 'data_bulanan', 'data_tahunan', 'data_lima_tahun', 'data_satu_tahun', 'data_tiga_tahun']; 548)
[2025-06-12T08:09:44.511+0000] {local_task_job_runner.py:225} INFO - Task exited with return code 1
[2025-06-12T08:09:44.671+0000] {taskinstance.py:2653} INFO - 0 downstream tasks scheduled from follow-on schedule check
