[2025-06-12T09:05:01.526+0000] {taskinstance.py:1103} INFO - Dependencies all met for dep_context=non-requeueable deps ti=<TaskInstance: yfinance_pipeline.extract_yfinance manual__2025-06-12T09:04:59.769943+00:00 [queued]>
[2025-06-12T09:05:01.542+0000] {taskinstance.py:1103} INFO - Dependencies all met for dep_context=requeueable deps ti=<TaskInstance: yfinance_pipeline.extract_yfinance manual__2025-06-12T09:04:59.769943+00:00 [queued]>
[2025-06-12T09:05:01.542+0000] {taskinstance.py:1308} INFO - Starting attempt 1 of 2
[2025-06-12T09:05:01.569+0000] {taskinstance.py:1327} INFO - Executing <Task(DockerOperator): extract_yfinance> on 2025-06-12 09:04:59.769943+00:00
[2025-06-12T09:05:01.578+0000] {standard_task_runner.py:57} INFO - Started process 222 to run task
[2025-06-12T09:05:01.583+0000] {standard_task_runner.py:84} INFO - Running: ['***', 'tasks', 'run', 'yfinance_pipeline', 'extract_yfinance', 'manual__2025-06-12T09:04:59.769943+00:00', '--job-id', '25', '--raw', '--subdir', 'DAGS_FOLDER/yfinance_pipeline_dag.py', '--cfg-path', '/tmp/tmp1mab28d8']
[2025-06-12T09:05:01.584+0000] {standard_task_runner.py:85} INFO - Job 25: Subtask extract_yfinance
[2025-06-12T09:05:01.662+0000] {task_command.py:410} INFO - Running <TaskInstance: yfinance_pipeline.extract_yfinance manual__2025-06-12T09:04:59.769943+00:00 [running]> on host c8950c9ffc98
[2025-06-12T09:05:01.858+0000] {taskinstance.py:1547} INFO - Exporting env vars: AIRFLOW_CTX_DAG_OWNER='***' AIRFLOW_CTX_DAG_ID='yfinance_pipeline' AIRFLOW_CTX_TASK_ID='extract_yfinance' AIRFLOW_CTX_EXECUTION_DATE='2025-06-12T09:04:59.769943+00:00' AIRFLOW_CTX_TRY_NUMBER='1' AIRFLOW_CTX_DAG_RUN_ID='manual__2025-06-12T09:04:59.769943+00:00'
[2025-06-12T09:05:01.990+0000] {docker.py:334} INFO - Starting docker container from image yfinance_extraction:latest
[2025-06-12T09:05:02.059+0000] {taskinstance.py:1824} ERROR - Task failed with exception
Traceback (most recent call last):
  File "/home/airflow/.local/lib/python3.7/site-packages/docker/api/client.py", line 268, in _raise_for_status
    response.raise_for_status()
  File "/home/airflow/.local/lib/python3.7/site-packages/requests/models.py", line 1021, in raise_for_status
    raise HTTPError(http_error_msg, response=self)
requests.exceptions.HTTPError: 409 Client Error: Conflict for url: http+docker://localhost/v1.48/containers/create?name=pipeline_extract_yfinance

The above exception was the direct cause of the following exception:

Traceback (most recent call last):
  File "/home/airflow/.local/lib/python3.7/site-packages/airflow/providers/docker/operators/docker.py", line 478, in execute
    return self._run_image()
  File "/home/airflow/.local/lib/python3.7/site-packages/airflow/providers/docker/operators/docker.py", line 351, in _run_image
    return self._run_image_with_mounts(self.mounts, add_tmp_variable=False)
  File "/home/airflow/.local/lib/python3.7/site-packages/airflow/providers/docker/operators/docker.py", line 393, in _run_image_with_mounts
    hostname=self.hostname,
  File "/home/airflow/.local/lib/python3.7/site-packages/docker/api/container.py", line 431, in create_container
    return self.create_container_from_config(config, name, platform)
  File "/home/airflow/.local/lib/python3.7/site-packages/docker/api/container.py", line 448, in create_container_from_config
    return self._result(res, True)
  File "/home/airflow/.local/lib/python3.7/site-packages/docker/api/client.py", line 274, in _result
    self._raise_for_status(response)
  File "/home/airflow/.local/lib/python3.7/site-packages/docker/api/client.py", line 270, in _raise_for_status
    raise create_api_error_from_http_exception(e) from e
  File "/home/airflow/.local/lib/python3.7/site-packages/docker/errors.py", line 39, in create_api_error_from_http_exception
    raise cls(e, response=response, explanation=explanation) from e
docker.errors.APIError: 409 Client Error for http+docker://localhost/v1.48/containers/create?name=pipeline_extract_yfinance: Conflict ("Conflict. The container name "/pipeline_extract_yfinance" is already in use by container "02dda0933bb985d8280f35814ca76c1a443b5f54e43f9d47b37ff34de57f4ecc". You have to remove (or rename) that container to be able to reuse that name.")
[2025-06-12T09:05:02.127+0000] {taskinstance.py:1350} INFO - Marking task as UP_FOR_RETRY. dag_id=yfinance_pipeline, task_id=extract_yfinance, execution_date=20250612T090459, start_date=20250612T090501, end_date=20250612T090502
[2025-06-12T09:05:02.200+0000] {standard_task_runner.py:109} ERROR - Failed to execute job 25 for task extract_yfinance (409 Client Error for http+docker://localhost/v1.48/containers/create?name=pipeline_extract_yfinance: Conflict ("Conflict. The container name "/pipeline_extract_yfinance" is already in use by container "02dda0933bb985d8280f35814ca76c1a443b5f54e43f9d47b37ff34de57f4ecc". You have to remove (or rename) that container to be able to reuse that name."); 222)
[2025-06-12T09:05:02.238+0000] {local_task_job_runner.py:225} INFO - Task exited with return code 1
[2025-06-12T09:05:02.294+0000] {taskinstance.py:2653} INFO - 0 downstream tasks scheduled from follow-on schedule check
